<!-- Robot limits pulled from https://frankaemika.github.io/docs/control_parameters.html#constants -->
<!-- Modified from the original source code at
        1) https://github.com/vikashplus/franka
    which was originally written by Vikash Kumar and licensed under the Apache License= -->

<mujocoinclude>
	<body name="panda0_link0" childclass="panda" >
        <geom class="panda_viz" mesh="link0_viz" rgba="0 0 0 0"/>
        <geom class="panda_col" mesh="link0_col" mass="2.91242" rgba="0 0 0 0"/>
        <body name="panda0_link1" pos="0 0 0.333">
            <joint name="panda0_joint1" range="-2.8973 2.8973" class="panda_arm"/>
            <geom class="panda_viz" mesh="link1_viz" rgba="0 0 0 0"/> 
            <geom class="panda_col" mesh="link1_col" mass="2.7063" rgba="0 0 0 0"/>
            <body name="panda0_link2" pos="0 0 0" quat="0.707107 -0.707107 0 0">
                <joint name="panda0_joint2" range="-1.7628 1.7628" class="panda_arm"/>
                <geom class="panda_viz" mesh="link2_viz" rgba="0 0 0 0"/>
                <geom class="panda_col" mesh="link2_col" mass="2.73046" rgba="0 0 0 0"/>
                <body name="panda0_link3" pos="0 -0.316 0" quat="0.707107 0.707107 0 0">
                    <joint name="panda0_joint3" range="-2.8973 2.8973" class="panda_arm"/>
                    <geom class="panda_viz" mesh="link3_viz" rgba="0 0 0 0"/>
                    <geom class="panda_col" mesh="link3_col" mass="2.04104" rgba="0 0 0 0"/>
                    <body name="panda0_link4" pos="0.0825 0 0" quat="0.707107 0.707107 0 0">
                        <joint name="panda0_joint4" range="-3.0718 -0.4" class="panda_arm"/>
                        <geom class="panda_viz" mesh="link4_viz" rgba="0 0 0 0" />
                        <geom class="panda_col" mesh="link4_col" mass="2.08129" rgba="0 0 0 0"/>
                        <body name="panda0_link5" pos="-0.0825 0.384 0" quat="0.707107 -0.707107 0 0">
                            <joint name="panda0_joint5" range="-2.8973 2.8973" class="panda_forearm"/>
                            <geom class="panda_viz" mesh="link5_viz" rgba="0 0 0 0"/>
                            <geom class="panda_col" mesh="link5_col" mass="3.00049" rgba="0 0 0 0"/>
                            <body name="panda0_link6" pos="0 0 0" euler='1.57 0 1.57'>
                                <joint name="panda0_joint6" range="-1.6573 2.1127" class="panda_forearm"/>
                                <!-- <body name="panda0_link6" pos="0 0 0" quat="0.707107 0.707107 0 0"> -->
                                <!-- <joint name="panda0_joint6" range="-0.0873 3.8223" class="panda_forearm"/> -->
                                <geom class="panda_viz" mesh="link6_viz" rgba="0 0 0 0"/>
                                <geom class="panda_col" mesh="link6_col" mass="1.3235" rgba="0 0 0 0"/>
                                <body name="panda0_link7" pos="0.088 0 0" euler='1.57 0 0.7854'>
                                    <joint name="panda0_joint7" range="-2.8973 2.8973" class="panda_forearm"/>
                                    <!-- <body name="panda0_link7" pos="0.088 0 0" quat="0.707107 0.707107 0 0"> -->
                                    <!-- <joint name="panda0_joint7" range="-2.9671 2.9671" class="panda_forearm"/> -->
                                    <geom class="panda_viz" mesh="link7_viz" rgba="0 0 0 0"/>
                                    <geom class="panda_col" mesh="link7_col" mass="0.2" rgba="0 0 0 0"/>
                                    <geom pos="0 0 0.107" quat="0.92388 0 0 -0.382683" class="panda_viz" mesh="hand_viz" rgba="0 0 0 0"/>
                                    <geom pos="0 0 0.107" quat="0.92388 0 0 -0.382683" class="panda_col" mesh="hand_col" mass="0.81909" rgba="0 0 0 0"/>
                                    <site name='end_effector' pos='0 0 .210' size='0.01' euler='0 0 -0.785398'/>
                                        <body name="panda0_leftfinger" pos="0 0 0.1654" quat="0.92388 0 0 -0.382683">
                                            <inertial pos="-1.57863e-05 0.0118731 0.0434103" quat="0.705868 0.0310348 -0.0314925 0.706962" mass="0.0927059" diaginertia="6.57134e-05 6.09611e-05 1.09932e-05" />
                                            <joint name="panda0_finger_joint1"  axis="0 1 0" type="slide" range="0 0.04"/>
                                            <!-- <geom class="panda_viz" mesh="finger_viz"/> -->
                                            <geom size="0.05" type="sphere" rgba=".95 .99 .92 1" />
                                        </body>
                                        <body name="panda0_rightfinger" pos="0 0 0.1654" quat="0.92388 0 0 -0.382683" >
                                            <inertial pos="-1.57863e-05 0.0118731 0.0434103" quat="0.705868 0.0310348 -0.0314925 0.706962" mass="0.0927059" diaginertia="6.57134e-05 6.09611e-05 1.09932e-05" />
                                            <joint name="panda0_finger_joint2"  axis="0 1 0" type="slide" range="0 0.04" />
                                            <!-- <geom class="panda_viz" mesh="finger_viz"/> -->
                                            <geom size="0.05" type="sphere" rgba=".95 .99 .92 1" />
                                        </body>
                                </body>
                            </body>
                        </body>
                    </body>
                </body>
            </body>
        </body>
    </body>
</mujocoinclude>
